[2022-10-14T01:38:23.654+0000] {taskinstance.py:1165} INFO - Dependencies all met for <TaskInstance: DAG_cines.get_data manual__2022-10-14T01:38:16.243667+00:00 [queued]>
[2022-10-14T01:38:23.664+0000] {taskinstance.py:1165} INFO - Dependencies all met for <TaskInstance: DAG_cines.get_data manual__2022-10-14T01:38:16.243667+00:00 [queued]>
[2022-10-14T01:38:23.665+0000] {taskinstance.py:1362} INFO - 
--------------------------------------------------------------------------------
[2022-10-14T01:38:23.666+0000] {taskinstance.py:1363} INFO - Starting attempt 1 of 1
[2022-10-14T01:38:23.666+0000] {taskinstance.py:1364} INFO - 
--------------------------------------------------------------------------------
[2022-10-14T01:38:23.680+0000] {taskinstance.py:1383} INFO - Executing <Task(PythonOperator): get_data> on 2022-10-14 01:38:16.243667+00:00
[2022-10-14T01:38:23.685+0000] {standard_task_runner.py:54} INFO - Started process 53 to run task
[2022-10-14T01:38:23.690+0000] {standard_task_runner.py:82} INFO - Running: ['***', 'tasks', 'run', 'DAG_cines', 'get_data', 'manual__2022-10-14T01:38:16.243667+00:00', '--job-id', '39', '--raw', '--subdir', 'DAGS_FOLDER/DD_template.py', '--cfg-path', '/tmp/tmp20d0y56v']
[2022-10-14T01:38:23.691+0000] {standard_task_runner.py:83} INFO - Job 39: Subtask get_data
[2022-10-14T01:38:23.693+0000] {dagbag.py:525} INFO - Filling up the DagBag from /opt/***/dags/DD_template.py
[2022-10-14T01:38:23.886+0000] {task_command.py:384} INFO - Running <TaskInstance: DAG_cines.get_data manual__2022-10-14T01:38:16.243667+00:00 [running]> on host 7cb2e4b14eaa
[2022-10-14T01:38:23.931+0000] {taskinstance.py:1592} INFO - Exporting the following env vars:
AIRFLOW_CTX_DAG_OWNER=***
AIRFLOW_CTX_DAG_ID=DAG_cines
AIRFLOW_CTX_TASK_ID=get_data
AIRFLOW_CTX_EXECUTION_DATE=2022-10-14T01:38:16.243667+00:00
AIRFLOW_CTX_TRY_NUMBER=1
AIRFLOW_CTX_DAG_RUN_ID=manual__2022-10-14T01:38:16.243667+00:00
[2022-10-14T01:38:24.177+0000] {taskinstance.py:1851} ERROR - Task failed with exception
Traceback (most recent call last):
  File "/home/airflow/.local/lib/python3.7/site-packages/airflow/operators/python.py", line 175, in execute
    return_value = self.execute_callable()
  File "/home/airflow/.local/lib/python3.7/site-packages/airflow/operators/python.py", line 193, in execute_callable
    return self.python_callable(*self.op_args, **self.op_kwargs)
  File "/opt/airflow/dags/DD_template.py", line 21, in get_data
    url = config('DATOS_MUSEOS')
  File "/home/airflow/.local/lib/python3.7/site-packages/decouple.py", line 243, in __call__
    return self.config(*args, **kwargs)
  File "/home/airflow/.local/lib/python3.7/site-packages/decouple.py", line 105, in __call__
    return self.get(*args, **kwargs)
  File "/home/airflow/.local/lib/python3.7/site-packages/decouple.py", line 90, in get
    raise UndefinedValueError('{} not found. Declare it as envvar or define a default value.'.format(option))
decouple.UndefinedValueError: DATOS_MUSEOS not found. Declare it as envvar or define a default value.
[2022-10-14T01:38:24.191+0000] {taskinstance.py:1406} INFO - Marking task as FAILED. dag_id=DAG_cines, task_id=get_data, execution_date=20221014T013816, start_date=20221014T013823, end_date=20221014T013824
[2022-10-14T01:38:24.212+0000] {standard_task_runner.py:107} ERROR - Failed to execute job 39 for task get_data (DATOS_MUSEOS not found. Declare it as envvar or define a default value.; 53)
[2022-10-14T01:38:24.268+0000] {local_task_job.py:164} INFO - Task exited with return code 1
[2022-10-14T01:38:24.296+0000] {local_task_job.py:273} INFO - 0 downstream tasks scheduled from follow-on schedule check
