[2022-10-14T15:04:58.084+0000] {taskinstance.py:1165} INFO - Dependencies all met for <TaskInstance: DAG_cines.transform_data manual__2022-10-14T15:04:52.690947+00:00 [queued]>
[2022-10-14T15:04:58.091+0000] {taskinstance.py:1165} INFO - Dependencies all met for <TaskInstance: DAG_cines.transform_data manual__2022-10-14T15:04:52.690947+00:00 [queued]>
[2022-10-14T15:04:58.092+0000] {taskinstance.py:1362} INFO - 
--------------------------------------------------------------------------------
[2022-10-14T15:04:58.093+0000] {taskinstance.py:1363} INFO - Starting attempt 1 of 1
[2022-10-14T15:04:58.094+0000] {taskinstance.py:1364} INFO - 
--------------------------------------------------------------------------------
[2022-10-14T15:04:58.103+0000] {taskinstance.py:1383} INFO - Executing <Task(PythonOperator): transform_data> on 2022-10-14 15:04:52.690947+00:00
[2022-10-14T15:04:58.108+0000] {standard_task_runner.py:54} INFO - Started process 85 to run task
[2022-10-14T15:04:58.111+0000] {standard_task_runner.py:82} INFO - Running: ['***', 'tasks', 'run', 'DAG_cines', 'transform_data', 'manual__2022-10-14T15:04:52.690947+00:00', '--job-id', '113', '--raw', '--subdir', 'DAGS_FOLDER/DD_template.py', '--cfg-path', '/tmp/tmpgtpj4pxq']
[2022-10-14T15:04:58.113+0000] {standard_task_runner.py:83} INFO - Job 113: Subtask transform_data
[2022-10-14T15:04:58.115+0000] {dagbag.py:525} INFO - Filling up the DagBag from /opt/***/dags/DD_template.py
[2022-10-14T15:04:58.236+0000] {task_command.py:384} INFO - Running <TaskInstance: DAG_cines.transform_data manual__2022-10-14T15:04:52.690947+00:00 [running]> on host 3179f9ebe339
[2022-10-14T15:04:58.277+0000] {taskinstance.py:1592} INFO - Exporting the following env vars:
AIRFLOW_CTX_DAG_OWNER=***
AIRFLOW_CTX_DAG_ID=DAG_cines
AIRFLOW_CTX_TASK_ID=transform_data
AIRFLOW_CTX_EXECUTION_DATE=2022-10-14T15:04:52.690947+00:00
AIRFLOW_CTX_TRY_NUMBER=1
AIRFLOW_CTX_DAG_RUN_ID=manual__2022-10-14T15:04:52.690947+00:00
[2022-10-14T15:04:58.448+0000] {taskinstance.py:1851} ERROR - Task failed with exception
Traceback (most recent call last):
  File "/home/airflow/.local/lib/python3.7/site-packages/airflow/operators/python.py", line 175, in execute
    return_value = self.execute_callable()
  File "/home/airflow/.local/lib/python3.7/site-packages/airflow/operators/python.py", line 193, in execute_callable
    return self.python_callable(*self.op_args, **self.op_kwargs)
  File "/opt/airflow/dags/DD_template.py", line 235, in transform_data
    last = get_col_of_insterest(last)
  File "/opt/airflow/dags/DD_template.py", line 138, in get_col_of_insterest
    return df[cols]
  File "/home/airflow/.local/lib/python3.7/site-packages/pandas/core/frame.py", line 3464, in __getitem__
    indexer = self.loc._get_listlike_indexer(key, axis=1)[1]
  File "/home/airflow/.local/lib/python3.7/site-packages/pandas/core/indexing.py", line 1314, in _get_listlike_indexer
    self._validate_read_indexer(keyarr, indexer, axis)
  File "/home/airflow/.local/lib/python3.7/site-packages/pandas/core/indexing.py", line 1377, in _validate_read_indexer
    raise KeyError(f"{not_found} not in index")
KeyError: "['cod_localidad', 'id_provincia', 'id_departamento', 'provincia', 'localidad'] not in index"
[2022-10-14T15:04:58.464+0000] {taskinstance.py:1406} INFO - Marking task as FAILED. dag_id=DAG_cines, task_id=transform_data, execution_date=20221014T150452, start_date=20221014T150458, end_date=20221014T150458
[2022-10-14T15:04:58.484+0000] {standard_task_runner.py:107} ERROR - Failed to execute job 113 for task transform_data ("['cod_localidad', 'id_provincia', 'id_departamento', 'provincia', 'localidad'] not in index"; 85)
[2022-10-14T15:04:58.534+0000] {local_task_job.py:164} INFO - Task exited with return code 1
[2022-10-14T15:04:58.570+0000] {local_task_job.py:273} INFO - 0 downstream tasks scheduled from follow-on schedule check
