[2022-10-14T21:45:56.275+0000] {taskinstance.py:1165} INFO - Dependencies all met for <TaskInstance: DAG_cines.transform_data manual__2022-10-14T21:45:51.749175+00:00 [queued]>
[2022-10-14T21:45:56.282+0000] {taskinstance.py:1165} INFO - Dependencies all met for <TaskInstance: DAG_cines.transform_data manual__2022-10-14T21:45:51.749175+00:00 [queued]>
[2022-10-14T21:45:56.284+0000] {taskinstance.py:1362} INFO - 
--------------------------------------------------------------------------------
[2022-10-14T21:45:56.285+0000] {taskinstance.py:1363} INFO - Starting attempt 1 of 1
[2022-10-14T21:45:56.286+0000] {taskinstance.py:1364} INFO - 
--------------------------------------------------------------------------------
[2022-10-14T21:45:56.294+0000] {taskinstance.py:1383} INFO - Executing <Task(PythonOperator): transform_data> on 2022-10-14 21:45:51.749175+00:00
[2022-10-14T21:45:56.301+0000] {standard_task_runner.py:54} INFO - Started process 233 to run task
[2022-10-14T21:45:56.305+0000] {standard_task_runner.py:82} INFO - Running: ['***', 'tasks', 'run', 'DAG_cines', 'transform_data', 'manual__2022-10-14T21:45:51.749175+00:00', '--job-id', '117', '--raw', '--subdir', 'DAGS_FOLDER/DD_template.py', '--cfg-path', '/tmp/tmplabhmt8l']
[2022-10-14T21:45:56.306+0000] {standard_task_runner.py:83} INFO - Job 117: Subtask transform_data
[2022-10-14T21:45:56.308+0000] {dagbag.py:525} INFO - Filling up the DagBag from /opt/***/dags/DD_template.py
[2022-10-14T21:45:56.461+0000] {task_command.py:384} INFO - Running <TaskInstance: DAG_cines.transform_data manual__2022-10-14T21:45:51.749175+00:00 [running]> on host e0ff8f96cc52
[2022-10-14T21:45:56.544+0000] {taskinstance.py:1592} INFO - Exporting the following env vars:
AIRFLOW_CTX_DAG_OWNER=***
AIRFLOW_CTX_DAG_ID=DAG_cines
AIRFLOW_CTX_TASK_ID=transform_data
AIRFLOW_CTX_EXECUTION_DATE=2022-10-14T21:45:51.749175+00:00
AIRFLOW_CTX_TRY_NUMBER=1
AIRFLOW_CTX_DAG_RUN_ID=manual__2022-10-14T21:45:51.749175+00:00
[2022-10-14T21:45:56.548+0000] {taskinstance.py:1851} ERROR - Task failed with exception
Traceback (most recent call last):
  File "/home/airflow/.local/lib/python3.7/site-packages/airflow/operators/python.py", line 175, in execute
    return_value = self.execute_callable()
  File "/home/airflow/.local/lib/python3.7/site-packages/airflow/operators/python.py", line 193, in execute_callable
    return self.python_callable(*self.op_args, **self.op_kwargs)
  File "/opt/airflow/dags/DD_template.py", line 109, in transform_data
    last = pd.read_csv('files/bibliotecas/last_bibliotecas_data.csv')
  File "/home/airflow/.local/lib/python3.7/site-packages/pandas/util/_decorators.py", line 311, in wrapper
    return func(*args, **kwargs)
  File "/home/airflow/.local/lib/python3.7/site-packages/pandas/io/parsers/readers.py", line 586, in read_csv
    return _read(filepath_or_buffer, kwds)
  File "/home/airflow/.local/lib/python3.7/site-packages/pandas/io/parsers/readers.py", line 482, in _read
    parser = TextFileReader(filepath_or_buffer, **kwds)
  File "/home/airflow/.local/lib/python3.7/site-packages/pandas/io/parsers/readers.py", line 811, in __init__
    self._engine = self._make_engine(self.engine)
  File "/home/airflow/.local/lib/python3.7/site-packages/pandas/io/parsers/readers.py", line 1040, in _make_engine
    return mapping[engine](self.f, **self.options)  # type: ignore[call-arg]
  File "/home/airflow/.local/lib/python3.7/site-packages/pandas/io/parsers/c_parser_wrapper.py", line 51, in __init__
    self._open_handles(src, kwds)
  File "/home/airflow/.local/lib/python3.7/site-packages/pandas/io/parsers/base_parser.py", line 229, in _open_handles
    errors=kwds.get("encoding_errors", "strict"),
  File "/home/airflow/.local/lib/python3.7/site-packages/pandas/io/common.py", line 707, in get_handle
    newline="",
FileNotFoundError: [Errno 2] No such file or directory: 'files/bibliotecas/last_bibliotecas_data.csv'
[2022-10-14T21:45:56.563+0000] {taskinstance.py:1406} INFO - Marking task as FAILED. dag_id=DAG_cines, task_id=transform_data, execution_date=20221014T214551, start_date=20221014T214556, end_date=20221014T214556
[2022-10-14T21:45:56.581+0000] {standard_task_runner.py:107} ERROR - Failed to execute job 117 for task transform_data ([Errno 2] No such file or directory: 'files/bibliotecas/last_bibliotecas_data.csv'; 233)
[2022-10-14T21:45:56.600+0000] {local_task_job.py:164} INFO - Task exited with return code 1
[2022-10-14T21:45:56.645+0000] {local_task_job.py:273} INFO - 0 downstream tasks scheduled from follow-on schedule check
