[2022-10-17T14:41:35.962+0000] {taskinstance.py:1165} INFO - Dependencies all met for <TaskInstance: DAG_museo.transform_data manual__2022-10-17T14:41:32.814227+00:00 [queued]>
[2022-10-17T14:41:35.969+0000] {taskinstance.py:1165} INFO - Dependencies all met for <TaskInstance: DAG_museo.transform_data manual__2022-10-17T14:41:32.814227+00:00 [queued]>
[2022-10-17T14:41:35.971+0000] {taskinstance.py:1362} INFO - 
--------------------------------------------------------------------------------
[2022-10-17T14:41:35.972+0000] {taskinstance.py:1363} INFO - Starting attempt 1 of 1
[2022-10-17T14:41:35.973+0000] {taskinstance.py:1364} INFO - 
--------------------------------------------------------------------------------
[2022-10-17T14:41:35.987+0000] {taskinstance.py:1383} INFO - Executing <Task(PythonOperator): transform_data> on 2022-10-17 14:41:32.814227+00:00
[2022-10-17T14:41:35.992+0000] {standard_task_runner.py:54} INFO - Started process 1000 to run task
[2022-10-17T14:41:35.995+0000] {standard_task_runner.py:82} INFO - Running: ['***', 'tasks', 'run', 'DAG_museo', 'transform_data', 'manual__2022-10-17T14:41:32.814227+00:00', '--job-id', '190', '--raw', '--subdir', 'DAGS_FOLDER/DAG_museo.py', '--cfg-path', '/tmp/tmpxs56ahfv']
[2022-10-17T14:41:35.996+0000] {standard_task_runner.py:83} INFO - Job 190: Subtask transform_data
[2022-10-17T14:41:35.998+0000] {dagbag.py:525} INFO - Filling up the DagBag from /opt/***/dags/DAG_museo.py
[2022-10-17T14:41:36.219+0000] {task_command.py:384} INFO - Running <TaskInstance: DAG_museo.transform_data manual__2022-10-17T14:41:32.814227+00:00 [running]> on host 067073ba6286
[2022-10-17T14:41:36.257+0000] {taskinstance.py:1592} INFO - Exporting the following env vars:
AIRFLOW_CTX_DAG_OWNER=***
AIRFLOW_CTX_DAG_ID=DAG_museo
AIRFLOW_CTX_TASK_ID=transform_data
AIRFLOW_CTX_EXECUTION_DATE=2022-10-17T14:41:32.814227+00:00
AIRFLOW_CTX_TRY_NUMBER=1
AIRFLOW_CTX_DAG_RUN_ID=manual__2022-10-17T14:41:32.814227+00:00
[2022-10-17T14:41:36.299+0000] {taskinstance.py:1851} ERROR - Task failed with exception
Traceback (most recent call last):
  File "/home/airflow/.local/lib/python3.7/site-packages/pandas/core/indexes/base.py", line 3361, in get_loc
    return self._engine.get_loc(casted_key)
  File "pandas/_libs/index.pyx", line 76, in pandas._libs.index.IndexEngine.get_loc
  File "pandas/_libs/index.pyx", line 108, in pandas._libs.index.IndexEngine.get_loc
  File "pandas/_libs/hashtable_class_helper.pxi", line 5198, in pandas._libs.hashtable.PyObjectHashTable.get_item
  File "pandas/_libs/hashtable_class_helper.pxi", line 5206, in pandas._libs.hashtable.PyObjectHashTable.get_item
KeyError: 'a単o_inaguracion'

The above exception was the direct cause of the following exception:

Traceback (most recent call last):
  File "/home/airflow/.local/lib/python3.7/site-packages/airflow/operators/python.py", line 175, in execute
    return_value = self.execute_callable()
  File "/home/airflow/.local/lib/python3.7/site-packages/airflow/operators/python.py", line 193, in execute_callable
    return self.python_callable(*self.op_args, **self.op_kwargs)
  File "/opt/airflow/dags/DAG_museo.py", line 242, in transform_data
    last = clean_columns(last)
  File "/opt/airflow/dags/DAG_museo.py", line 191, in clean_columns
    dataframe['a単o_inaguracion'].values
  File "/home/airflow/.local/lib/python3.7/site-packages/pandas/core/frame.py", line 3458, in __getitem__
    indexer = self.columns.get_loc(key)
  File "/home/airflow/.local/lib/python3.7/site-packages/pandas/core/indexes/base.py", line 3363, in get_loc
    raise KeyError(key) from err
KeyError: 'a単o_inaguracion'
[2022-10-17T14:41:36.315+0000] {taskinstance.py:1406} INFO - Marking task as FAILED. dag_id=DAG_museo, task_id=transform_data, execution_date=20221017T144132, start_date=20221017T144135, end_date=20221017T144136
[2022-10-17T14:41:36.324+0000] {standard_task_runner.py:107} ERROR - Failed to execute job 190 for task transform_data ('a単o_inaguracion'; 1000)
[2022-10-17T14:41:36.341+0000] {local_task_job.py:164} INFO - Task exited with return code 1
[2022-10-17T14:41:36.359+0000] {local_task_job.py:273} INFO - 0 downstream tasks scheduled from follow-on schedule check
