[2022-10-14T13:28:13.686+0000] {taskinstance.py:1165} INFO - Dependencies all met for <TaskInstance: DAG_cines.get_data manual__2022-10-14T13:28:06.257472+00:00 [queued]>
[2022-10-14T13:28:13.706+0000] {taskinstance.py:1165} INFO - Dependencies all met for <TaskInstance: DAG_cines.get_data manual__2022-10-14T13:28:06.257472+00:00 [queued]>
[2022-10-14T13:28:13.707+0000] {taskinstance.py:1362} INFO - 
--------------------------------------------------------------------------------
[2022-10-14T13:28:13.708+0000] {taskinstance.py:1363} INFO - Starting attempt 1 of 1
[2022-10-14T13:28:13.709+0000] {taskinstance.py:1364} INFO - 
--------------------------------------------------------------------------------
[2022-10-14T13:28:13.735+0000] {taskinstance.py:1383} INFO - Executing <Task(PythonOperator): get_data> on 2022-10-14 13:28:06.257472+00:00
[2022-10-14T13:28:13.741+0000] {standard_task_runner.py:54} INFO - Started process 122 to run task
[2022-10-14T13:28:13.746+0000] {standard_task_runner.py:82} INFO - Running: ['***', 'tasks', 'run', 'DAG_cines', 'get_data', 'manual__2022-10-14T13:28:06.257472+00:00', '--job-id', '93', '--raw', '--subdir', 'DAGS_FOLDER/DD_template.py', '--cfg-path', '/tmp/tmpcmtv4lbd']
[2022-10-14T13:28:13.748+0000] {standard_task_runner.py:83} INFO - Job 93: Subtask get_data
[2022-10-14T13:28:13.752+0000] {dagbag.py:525} INFO - Filling up the DagBag from /opt/***/dags/DD_template.py
[2022-10-14T13:28:14.295+0000] {task_command.py:384} INFO - Running <TaskInstance: DAG_cines.get_data manual__2022-10-14T13:28:06.257472+00:00 [running]> on host 51be23f3a6ba
[2022-10-14T13:28:14.482+0000] {taskinstance.py:1592} INFO - Exporting the following env vars:
AIRFLOW_CTX_DAG_OWNER=***
AIRFLOW_CTX_DAG_ID=DAG_cines
AIRFLOW_CTX_TASK_ID=get_data
AIRFLOW_CTX_EXECUTION_DATE=2022-10-14T13:28:06.257472+00:00
AIRFLOW_CTX_TRY_NUMBER=1
AIRFLOW_CTX_DAG_RUN_ID=manual__2022-10-14T13:28:06.257472+00:00
[2022-10-14T13:28:18.262+0000] {taskinstance.py:1851} ERROR - Task failed with exception
Traceback (most recent call last):
  File "/home/airflow/.local/lib/python3.7/site-packages/airflow/operators/python.py", line 175, in execute
    return_value = self.execute_callable()
  File "/home/airflow/.local/lib/python3.7/site-packages/airflow/operators/python.py", line 193, in execute_callable
    return self.python_callable(*self.op_args, **self.op_kwargs)
  File "/opt/airflow/dags/DD_template.py", line 76, in get_data
    raise "manualy stopped"
TypeError: exceptions must derive from BaseException
[2022-10-14T13:28:18.517+0000] {taskinstance.py:1406} INFO - Marking task as FAILED. dag_id=DAG_cines, task_id=get_data, execution_date=20221014T132806, start_date=20221014T132813, end_date=20221014T132818
[2022-10-14T13:28:18.832+0000] {standard_task_runner.py:107} ERROR - Failed to execute job 93 for task get_data (exceptions must derive from BaseException; 122)
[2022-10-14T13:28:19.057+0000] {local_task_job.py:164} INFO - Task exited with return code 1
[2022-10-14T13:28:19.143+0000] {local_task_job.py:273} INFO - 0 downstream tasks scheduled from follow-on schedule check
