[2022-10-17T14:39:42.023+0000] {taskinstance.py:1165} INFO - Dependencies all met for <TaskInstance: DAG_museo.transform_data manual__2022-10-17T14:39:37.325321+00:00 [queued]>
[2022-10-17T14:39:42.030+0000] {taskinstance.py:1165} INFO - Dependencies all met for <TaskInstance: DAG_museo.transform_data manual__2022-10-17T14:39:37.325321+00:00 [queued]>
[2022-10-17T14:39:42.031+0000] {taskinstance.py:1362} INFO - 
--------------------------------------------------------------------------------
[2022-10-17T14:39:42.032+0000] {taskinstance.py:1363} INFO - Starting attempt 1 of 1
[2022-10-17T14:39:42.033+0000] {taskinstance.py:1364} INFO - 
--------------------------------------------------------------------------------
[2022-10-17T14:39:42.040+0000] {taskinstance.py:1383} INFO - Executing <Task(PythonOperator): transform_data> on 2022-10-17 14:39:37.325321+00:00
[2022-10-17T14:39:42.044+0000] {standard_task_runner.py:54} INFO - Started process 905 to run task
[2022-10-17T14:39:42.046+0000] {standard_task_runner.py:82} INFO - Running: ['***', 'tasks', 'run', 'DAG_museo', 'transform_data', 'manual__2022-10-17T14:39:37.325321+00:00', '--job-id', '188', '--raw', '--subdir', 'DAGS_FOLDER/DAG_museo.py', '--cfg-path', '/tmp/tmpc16o27nh']
[2022-10-17T14:39:42.048+0000] {standard_task_runner.py:83} INFO - Job 188: Subtask transform_data
[2022-10-17T14:39:42.049+0000] {dagbag.py:525} INFO - Filling up the DagBag from /opt/***/dags/DAG_museo.py
[2022-10-17T14:39:42.347+0000] {task_command.py:384} INFO - Running <TaskInstance: DAG_museo.transform_data manual__2022-10-17T14:39:37.325321+00:00 [running]> on host 067073ba6286
[2022-10-17T14:39:42.404+0000] {taskinstance.py:1592} INFO - Exporting the following env vars:
AIRFLOW_CTX_DAG_OWNER=***
AIRFLOW_CTX_DAG_ID=DAG_museo
AIRFLOW_CTX_TASK_ID=transform_data
AIRFLOW_CTX_EXECUTION_DATE=2022-10-17T14:39:37.325321+00:00
AIRFLOW_CTX_TRY_NUMBER=1
AIRFLOW_CTX_DAG_RUN_ID=manual__2022-10-17T14:39:37.325321+00:00
[2022-10-17T14:39:42.451+0000] {taskinstance.py:1851} ERROR - Task failed with exception
Traceback (most recent call last):
  File "/home/airflow/.local/lib/python3.7/site-packages/airflow/operators/python.py", line 175, in execute
    return_value = self.execute_callable()
  File "/home/airflow/.local/lib/python3.7/site-packages/airflow/operators/python.py", line 193, in execute_callable
    return self.python_callable(*self.op_args, **self.op_kwargs)
  File "/opt/airflow/dags/DAG_museo.py", line 241, in transform_data
    last = clean_columns(last)
  File "/opt/airflow/dags/DAG_museo.py", line 187, in clean_columns
    lambda x: x
TypeError: map() must have at least two arguments.
[2022-10-17T14:39:42.462+0000] {taskinstance.py:1406} INFO - Marking task as FAILED. dag_id=DAG_museo, task_id=transform_data, execution_date=20221017T143937, start_date=20221017T143942, end_date=20221017T143942
[2022-10-17T14:39:42.476+0000] {standard_task_runner.py:107} ERROR - Failed to execute job 188 for task transform_data (map() must have at least two arguments.; 905)
[2022-10-17T14:39:42.512+0000] {local_task_job.py:164} INFO - Task exited with return code 1
[2022-10-17T14:39:42.537+0000] {local_task_job.py:273} INFO - 0 downstream tasks scheduled from follow-on schedule check
