[2022-10-14T14:51:14.621+0000] {taskinstance.py:1165} INFO - Dependencies all met for <TaskInstance: DAG_cines.transform_data manual__2022-10-14T14:51:10.509332+00:00 [queued]>
[2022-10-14T14:51:14.628+0000] {taskinstance.py:1165} INFO - Dependencies all met for <TaskInstance: DAG_cines.transform_data manual__2022-10-14T14:51:10.509332+00:00 [queued]>
[2022-10-14T14:51:14.629+0000] {taskinstance.py:1362} INFO - 
--------------------------------------------------------------------------------
[2022-10-14T14:51:14.630+0000] {taskinstance.py:1363} INFO - Starting attempt 1 of 1
[2022-10-14T14:51:14.631+0000] {taskinstance.py:1364} INFO - 
--------------------------------------------------------------------------------
[2022-10-14T14:51:14.639+0000] {taskinstance.py:1383} INFO - Executing <Task(PythonOperator): transform_data> on 2022-10-14 14:51:10.509332+00:00
[2022-10-14T14:51:14.645+0000] {standard_task_runner.py:54} INFO - Started process 74 to run task
[2022-10-14T14:51:14.650+0000] {standard_task_runner.py:82} INFO - Running: ['***', 'tasks', 'run', 'DAG_cines', 'transform_data', 'manual__2022-10-14T14:51:10.509332+00:00', '--job-id', '103', '--raw', '--subdir', 'DAGS_FOLDER/DD_template.py', '--cfg-path', '/tmp/tmpai99vspn']
[2022-10-14T14:51:14.652+0000] {standard_task_runner.py:83} INFO - Job 103: Subtask transform_data
[2022-10-14T14:51:14.653+0000] {dagbag.py:525} INFO - Filling up the DagBag from /opt/***/dags/DD_template.py
[2022-10-14T14:51:14.777+0000] {task_command.py:384} INFO - Running <TaskInstance: DAG_cines.transform_data manual__2022-10-14T14:51:10.509332+00:00 [running]> on host a2feda71064f
[2022-10-14T14:51:14.817+0000] {taskinstance.py:1592} INFO - Exporting the following env vars:
AIRFLOW_CTX_DAG_OWNER=***
AIRFLOW_CTX_DAG_ID=DAG_cines
AIRFLOW_CTX_TASK_ID=transform_data
AIRFLOW_CTX_EXECUTION_DATE=2022-10-14T14:51:10.509332+00:00
AIRFLOW_CTX_TRY_NUMBER=1
AIRFLOW_CTX_DAG_RUN_ID=manual__2022-10-14T14:51:10.509332+00:00
[2022-10-14T14:51:14.985+0000] {taskinstance.py:1851} ERROR - Task failed with exception
Traceback (most recent call last):
  File "/home/airflow/.local/lib/python3.7/site-packages/airflow/operators/python.py", line 175, in execute
    return_value = self.execute_callable()
  File "/home/airflow/.local/lib/python3.7/site-packages/airflow/operators/python.py", line 193, in execute_callable
    return self.python_callable(*self.op_args, **self.op_kwargs)
  File "/opt/airflow/dags/DD_template.py", line 235, in transform_data
    last = get_col_of_insterest(last)
  File "/opt/airflow/dags/DD_template.py", line 138, in get_col_of_insterest
    return df[cols]
  File "/home/airflow/.local/lib/python3.7/site-packages/pandas/core/frame.py", line 3464, in __getitem__
    indexer = self.loc._get_listlike_indexer(key, axis=1)[1]
  File "/home/airflow/.local/lib/python3.7/site-packages/pandas/core/indexing.py", line 1314, in _get_listlike_indexer
    self._validate_read_indexer(keyarr, indexer, axis)
  File "/home/airflow/.local/lib/python3.7/site-packages/pandas/core/indexing.py", line 1377, in _validate_read_indexer
    raise KeyError(f"{not_found} not in index")
KeyError: "['numero_de_telefono', 'mail'] not in index"
[2022-10-14T14:51:15.000+0000] {taskinstance.py:1406} INFO - Marking task as FAILED. dag_id=DAG_cines, task_id=transform_data, execution_date=20221014T145110, start_date=20221014T145114, end_date=20221014T145115
[2022-10-14T14:51:15.010+0000] {standard_task_runner.py:107} ERROR - Failed to execute job 103 for task transform_data ("['numero_de_telefono', 'mail'] not in index"; 74)
[2022-10-14T14:51:15.031+0000] {local_task_job.py:164} INFO - Task exited with return code 1
[2022-10-14T14:51:15.059+0000] {local_task_job.py:273} INFO - 0 downstream tasks scheduled from follow-on schedule check
