[2022-10-13T21:29:17.891+0000] {taskinstance.py:1165} INFO - Dependencies all met for <TaskInstance: DAG_cines.get_data manual__2022-10-13T21:29:17.376927+00:00 [queued]>
[2022-10-13T21:29:17.898+0000] {taskinstance.py:1165} INFO - Dependencies all met for <TaskInstance: DAG_cines.get_data manual__2022-10-13T21:29:17.376927+00:00 [queued]>
[2022-10-13T21:29:17.899+0000] {taskinstance.py:1362} INFO - 
--------------------------------------------------------------------------------
[2022-10-13T21:29:17.900+0000] {taskinstance.py:1363} INFO - Starting attempt 1 of 1
[2022-10-13T21:29:17.900+0000] {taskinstance.py:1364} INFO - 
--------------------------------------------------------------------------------
[2022-10-13T21:29:17.908+0000] {taskinstance.py:1383} INFO - Executing <Task(PythonOperator): get_data> on 2022-10-13 21:29:17.376927+00:00
[2022-10-13T21:29:17.912+0000] {standard_task_runner.py:54} INFO - Started process 684 to run task
[2022-10-13T21:29:17.914+0000] {standard_task_runner.py:82} INFO - Running: ['***', 'tasks', 'run', 'DAG_cines', 'get_data', 'manual__2022-10-13T21:29:17.376927+00:00', '--job-id', '14', '--raw', '--subdir', 'DAGS_FOLDER/DD_template.py', '--cfg-path', '/tmp/tmpuxyi_2_b']
[2022-10-13T21:29:17.916+0000] {standard_task_runner.py:83} INFO - Job 14: Subtask get_data
[2022-10-13T21:29:17.917+0000] {dagbag.py:525} INFO - Filling up the DagBag from /opt/***/dags/DD_template.py
[2022-10-13T21:29:18.023+0000] {task_command.py:384} INFO - Running <TaskInstance: DAG_cines.get_data manual__2022-10-13T21:29:17.376927+00:00 [running]> on host 4712aee39a8d
[2022-10-13T21:29:18.059+0000] {taskinstance.py:1592} INFO - Exporting the following env vars:
AIRFLOW_CTX_DAG_OWNER=***
AIRFLOW_CTX_DAG_ID=DAG_cines
AIRFLOW_CTX_TASK_ID=get_data
AIRFLOW_CTX_EXECUTION_DATE=2022-10-13T21:29:17.376927+00:00
AIRFLOW_CTX_TRY_NUMBER=1
AIRFLOW_CTX_DAG_RUN_ID=manual__2022-10-13T21:29:17.376927+00:00
[2022-10-13T21:29:18.202+0000] {taskinstance.py:1851} ERROR - Task failed with exception
Traceback (most recent call last):
  File "/home/airflow/.local/lib/python3.7/site-packages/airflow/operators/python.py", line 175, in execute
    return_value = self.execute_callable()
  File "/home/airflow/.local/lib/python3.7/site-packages/airflow/operators/python.py", line 193, in execute_callable
    return self.python_callable(*self.op_args, **self.op_kwargs)
  File "/opt/airflow/dags/DD_template.py", line 16, in get_data
    from libs.functions import download_data, check_change_in_data
ModuleNotFoundError: No module named 'libs'
[2022-10-13T21:29:18.212+0000] {taskinstance.py:1406} INFO - Marking task as FAILED. dag_id=DAG_cines, task_id=get_data, execution_date=20221013T212917, start_date=20221013T212917, end_date=20221013T212918
[2022-10-13T21:29:18.219+0000] {standard_task_runner.py:107} ERROR - Failed to execute job 14 for task get_data (No module named 'libs'; 684)
[2022-10-13T21:29:18.254+0000] {local_task_job.py:164} INFO - Task exited with return code 1
[2022-10-13T21:29:18.279+0000] {local_task_job.py:273} INFO - 0 downstream tasks scheduled from follow-on schedule check
