[2022-10-17T14:34:04.709+0000] {taskinstance.py:1165} INFO - Dependencies all met for <TaskInstance: DAG_biblioteca.transform_data manual__2022-10-17T14:34:00.482160+00:00 [queued]>
[2022-10-17T14:34:04.715+0000] {taskinstance.py:1165} INFO - Dependencies all met for <TaskInstance: DAG_biblioteca.transform_data manual__2022-10-17T14:34:00.482160+00:00 [queued]>
[2022-10-17T14:34:04.716+0000] {taskinstance.py:1362} INFO - 
--------------------------------------------------------------------------------
[2022-10-17T14:34:04.717+0000] {taskinstance.py:1363} INFO - Starting attempt 1 of 1
[2022-10-17T14:34:04.718+0000] {taskinstance.py:1364} INFO - 
--------------------------------------------------------------------------------
[2022-10-17T14:34:04.726+0000] {taskinstance.py:1383} INFO - Executing <Task(PythonOperator): transform_data> on 2022-10-17 14:34:00.482160+00:00
[2022-10-17T14:34:04.730+0000] {standard_task_runner.py:54} INFO - Started process 570 to run task
[2022-10-17T14:34:04.733+0000] {standard_task_runner.py:82} INFO - Running: ['***', 'tasks', 'run', 'DAG_biblioteca', 'transform_data', 'manual__2022-10-17T14:34:00.482160+00:00', '--job-id', '172', '--raw', '--subdir', 'DAGS_FOLDER/DAG_biblioteca.py', '--cfg-path', '/tmp/tmpffx29fcs']
[2022-10-17T14:34:04.734+0000] {standard_task_runner.py:83} INFO - Job 172: Subtask transform_data
[2022-10-17T14:34:04.735+0000] {dagbag.py:525} INFO - Filling up the DagBag from /opt/***/dags/DAG_biblioteca.py
[2022-10-17T14:34:05.003+0000] {task_command.py:384} INFO - Running <TaskInstance: DAG_biblioteca.transform_data manual__2022-10-17T14:34:00.482160+00:00 [running]> on host 067073ba6286
[2022-10-17T14:34:05.046+0000] {taskinstance.py:1592} INFO - Exporting the following env vars:
AIRFLOW_CTX_DAG_OWNER=***
AIRFLOW_CTX_DAG_ID=DAG_biblioteca
AIRFLOW_CTX_TASK_ID=transform_data
AIRFLOW_CTX_EXECUTION_DATE=2022-10-17T14:34:00.482160+00:00
AIRFLOW_CTX_TRY_NUMBER=1
AIRFLOW_CTX_DAG_RUN_ID=manual__2022-10-17T14:34:00.482160+00:00
[2022-10-17T14:34:05.060+0000] {taskinstance.py:1851} ERROR - Task failed with exception
Traceback (most recent call last):
  File "/home/airflow/.local/lib/python3.7/site-packages/airflow/operators/python.py", line 175, in execute
    return_value = self.execute_callable()
  File "/home/airflow/.local/lib/python3.7/site-packages/airflow/operators/python.py", line 193, in execute_callable
    return self.python_callable(*self.op_args, **self.op_kwargs)
  File "/opt/airflow/dags/DAG_biblioteca.py", line 238, in transform_data
    last = get_cols_insterest(last)
  File "/opt/airflow/dags/DAG_biblioteca.py", line 111, in get_cols_insterest
    return dataframe[cols]
  File "/home/airflow/.local/lib/python3.7/site-packages/pandas/core/frame.py", line 3464, in __getitem__
    indexer = self.loc._get_listlike_indexer(key, axis=1)[1]
  File "/home/airflow/.local/lib/python3.7/site-packages/pandas/core/indexing.py", line 1314, in _get_listlike_indexer
    self._validate_read_indexer(keyarr, indexer, axis)
  File "/home/airflow/.local/lib/python3.7/site-packages/pandas/core/indexing.py", line 1377, in _validate_read_indexer
    raise KeyError(f"{not_found} not in index")
KeyError: "['año_actualizacion'] not in index"
[2022-10-17T14:34:05.071+0000] {taskinstance.py:1406} INFO - Marking task as FAILED. dag_id=DAG_biblioteca, task_id=transform_data, execution_date=20221017T143400, start_date=20221017T143404, end_date=20221017T143405
[2022-10-17T14:34:05.081+0000] {standard_task_runner.py:107} ERROR - Failed to execute job 172 for task transform_data ("['año_actualizacion'] not in index"; 570)
[2022-10-17T14:34:05.114+0000] {local_task_job.py:164} INFO - Task exited with return code 1
[2022-10-17T14:34:05.148+0000] {local_task_job.py:273} INFO - 0 downstream tasks scheduled from follow-on schedule check
