[2022-10-13T21:42:34.175+0000] {taskinstance.py:1165} INFO - Dependencies all met for <TaskInstance: DAG_cines.get_data manual__2022-10-13T21:42:33.117724+00:00 [queued]>
[2022-10-13T21:42:34.181+0000] {taskinstance.py:1165} INFO - Dependencies all met for <TaskInstance: DAG_cines.get_data manual__2022-10-13T21:42:33.117724+00:00 [queued]>
[2022-10-13T21:42:34.182+0000] {taskinstance.py:1362} INFO - 
--------------------------------------------------------------------------------
[2022-10-13T21:42:34.183+0000] {taskinstance.py:1363} INFO - Starting attempt 1 of 1
[2022-10-13T21:42:34.184+0000] {taskinstance.py:1364} INFO - 
--------------------------------------------------------------------------------
[2022-10-13T21:42:34.192+0000] {taskinstance.py:1383} INFO - Executing <Task(PythonOperator): get_data> on 2022-10-13 21:42:33.117724+00:00
[2022-10-13T21:42:34.196+0000] {standard_task_runner.py:54} INFO - Started process 1332 to run task
[2022-10-13T21:42:34.199+0000] {standard_task_runner.py:82} INFO - Running: ['***', 'tasks', 'run', 'DAG_cines', 'get_data', 'manual__2022-10-13T21:42:33.117724+00:00', '--job-id', '15', '--raw', '--subdir', 'DAGS_FOLDER/DD_template.py', '--cfg-path', '/tmp/tmpw0rgdmb8']
[2022-10-13T21:42:34.201+0000] {standard_task_runner.py:83} INFO - Job 15: Subtask get_data
[2022-10-13T21:42:34.202+0000] {dagbag.py:525} INFO - Filling up the DagBag from /opt/***/dags/DD_template.py
[2022-10-13T21:42:34.305+0000] {task_command.py:384} INFO - Running <TaskInstance: DAG_cines.get_data manual__2022-10-13T21:42:33.117724+00:00 [running]> on host 4712aee39a8d
[2022-10-13T21:42:34.342+0000] {taskinstance.py:1592} INFO - Exporting the following env vars:
AIRFLOW_CTX_DAG_OWNER=***
AIRFLOW_CTX_DAG_ID=DAG_cines
AIRFLOW_CTX_TASK_ID=get_data
AIRFLOW_CTX_EXECUTION_DATE=2022-10-13T21:42:33.117724+00:00
AIRFLOW_CTX_TRY_NUMBER=1
AIRFLOW_CTX_DAG_RUN_ID=manual__2022-10-13T21:42:33.117724+00:00
[2022-10-13T21:42:35.800+0000] {taskinstance.py:1851} ERROR - Task failed with exception
Traceback (most recent call last):
  File "/home/airflow/.local/lib/python3.7/site-packages/airflow/operators/python.py", line 175, in execute
    return_value = self.execute_callable()
  File "/home/airflow/.local/lib/python3.7/site-packages/airflow/operators/python.py", line 193, in execute_callable
    return self.python_callable(*self.op_args, **self.op_kwargs)
  File "/opt/airflow/dags/DD_template.py", line 48, in get_data
    index=False
  File "/home/airflow/.local/lib/python3.7/site-packages/pandas/core/generic.py", line 3482, in to_csv
    storage_options=storage_options,
  File "/home/airflow/.local/lib/python3.7/site-packages/pandas/io/formats/format.py", line 1105, in to_csv
    csv_formatter.save()
  File "/home/airflow/.local/lib/python3.7/site-packages/pandas/io/formats/csvs.py", line 243, in save
    storage_options=self.storage_options,
  File "/home/airflow/.local/lib/python3.7/site-packages/pandas/io/common.py", line 707, in get_handle
    newline="",
FileNotFoundError: [Errno 2] No such file or directory: 'datasets/cines/last_cines_data.csv'
[2022-10-13T21:42:35.824+0000] {taskinstance.py:1406} INFO - Marking task as FAILED. dag_id=DAG_cines, task_id=get_data, execution_date=20221013T214233, start_date=20221013T214234, end_date=20221013T214235
[2022-10-13T21:42:35.836+0000] {standard_task_runner.py:107} ERROR - Failed to execute job 15 for task get_data ([Errno 2] No such file or directory: 'datasets/cines/last_cines_data.csv'; 1332)
[2022-10-13T21:42:35.896+0000] {local_task_job.py:164} INFO - Task exited with return code 1
[2022-10-13T21:42:35.920+0000] {local_task_job.py:273} INFO - 0 downstream tasks scheduled from follow-on schedule check
