[2022-10-14T22:02:41.893+0000] {taskinstance.py:1165} INFO - Dependencies all met for <TaskInstance: DAG_cines.get_data manual__2022-10-14T22:02:40.584080+00:00 [queued]>
[2022-10-14T22:02:41.900+0000] {taskinstance.py:1165} INFO - Dependencies all met for <TaskInstance: DAG_cines.get_data manual__2022-10-14T22:02:40.584080+00:00 [queued]>
[2022-10-14T22:02:41.901+0000] {taskinstance.py:1362} INFO - 
--------------------------------------------------------------------------------
[2022-10-14T22:02:41.902+0000] {taskinstance.py:1363} INFO - Starting attempt 1 of 1
[2022-10-14T22:02:41.903+0000] {taskinstance.py:1364} INFO - 
--------------------------------------------------------------------------------
[2022-10-14T22:02:41.911+0000] {taskinstance.py:1383} INFO - Executing <Task(PythonOperator): get_data> on 2022-10-14 22:02:40.584080+00:00
[2022-10-14T22:02:41.916+0000] {standard_task_runner.py:54} INFO - Started process 1094 to run task
[2022-10-14T22:02:41.919+0000] {standard_task_runner.py:82} INFO - Running: ['***', 'tasks', 'run', 'DAG_cines', 'get_data', 'manual__2022-10-14T22:02:40.584080+00:00', '--job-id', '127', '--raw', '--subdir', 'DAGS_FOLDER/DD_template.py', '--cfg-path', '/tmp/tmp3s1tygdb']
[2022-10-14T22:02:41.920+0000] {standard_task_runner.py:83} INFO - Job 127: Subtask get_data
[2022-10-14T22:02:41.922+0000] {dagbag.py:525} INFO - Filling up the DagBag from /opt/***/dags/DD_template.py
[2022-10-14T22:02:42.049+0000] {task_command.py:384} INFO - Running <TaskInstance: DAG_cines.get_data manual__2022-10-14T22:02:40.584080+00:00 [running]> on host e0ff8f96cc52
[2022-10-14T22:02:42.089+0000] {taskinstance.py:1592} INFO - Exporting the following env vars:
AIRFLOW_CTX_DAG_OWNER=***
AIRFLOW_CTX_DAG_ID=DAG_cines
AIRFLOW_CTX_TASK_ID=get_data
AIRFLOW_CTX_EXECUTION_DATE=2022-10-14T22:02:40.584080+00:00
AIRFLOW_CTX_TRY_NUMBER=1
AIRFLOW_CTX_DAG_RUN_ID=manual__2022-10-14T22:02:40.584080+00:00
[2022-10-14T22:02:43.625+0000] {taskinstance.py:1851} ERROR - Task failed with exception
Traceback (most recent call last):
  File "/home/airflow/.local/lib/python3.7/site-packages/airflow/operators/python.py", line 175, in execute
    return_value = self.execute_callable()
  File "/home/airflow/.local/lib/python3.7/site-packages/airflow/operators/python.py", line 193, in execute_callable
    return self.python_callable(*self.op_args, **self.op_kwargs)
  File "/opt/airflow/dags/DD_template.py", line 69, in get_data
    last_df = pd.read.csv(Path(
  File "/home/airflow/.local/lib/python3.7/site-packages/pandas/__init__.py", line 244, in __getattr__
    raise AttributeError(f"module 'pandas' has no attribute '{name}'")
AttributeError: module 'pandas' has no attribute 'read'
[2022-10-14T22:02:43.645+0000] {taskinstance.py:1406} INFO - Marking task as FAILED. dag_id=DAG_cines, task_id=get_data, execution_date=20221014T220240, start_date=20221014T220241, end_date=20221014T220243
[2022-10-14T22:02:43.659+0000] {standard_task_runner.py:107} ERROR - Failed to execute job 127 for task get_data (module 'pandas' has no attribute 'read'; 1094)
[2022-10-14T22:02:43.720+0000] {local_task_job.py:164} INFO - Task exited with return code 1
[2022-10-14T22:02:43.753+0000] {local_task_job.py:273} INFO - 0 downstream tasks scheduled from follow-on schedule check
