[2022-10-14T13:28:09.227+0000] {taskinstance.py:1165} INFO - Dependencies all met for <TaskInstance: DAG_cines.get_data manual__2022-10-14T13:28:06.360505+00:00 [queued]>
[2022-10-14T13:28:09.245+0000] {taskinstance.py:1165} INFO - Dependencies all met for <TaskInstance: DAG_cines.get_data manual__2022-10-14T13:28:06.360505+00:00 [queued]>
[2022-10-14T13:28:09.246+0000] {taskinstance.py:1362} INFO - 
--------------------------------------------------------------------------------
[2022-10-14T13:28:09.249+0000] {taskinstance.py:1363} INFO - Starting attempt 1 of 1
[2022-10-14T13:28:09.255+0000] {taskinstance.py:1364} INFO - 
--------------------------------------------------------------------------------
[2022-10-14T13:28:09.277+0000] {taskinstance.py:1383} INFO - Executing <Task(PythonOperator): get_data> on 2022-10-14 13:28:06.360505+00:00
[2022-10-14T13:28:09.285+0000] {standard_task_runner.py:54} INFO - Started process 119 to run task
[2022-10-14T13:28:09.290+0000] {standard_task_runner.py:82} INFO - Running: ['***', 'tasks', 'run', 'DAG_cines', 'get_data', 'manual__2022-10-14T13:28:06.360505+00:00', '--job-id', '92', '--raw', '--subdir', 'DAGS_FOLDER/DD_template.py', '--cfg-path', '/tmp/tmp8eoapy0p']
[2022-10-14T13:28:09.292+0000] {standard_task_runner.py:83} INFO - Job 92: Subtask get_data
[2022-10-14T13:28:09.296+0000] {dagbag.py:525} INFO - Filling up the DagBag from /opt/***/dags/DD_template.py
[2022-10-14T13:28:12.400+0000] {task_command.py:384} INFO - Running <TaskInstance: DAG_cines.get_data manual__2022-10-14T13:28:06.360505+00:00 [running]> on host 51be23f3a6ba
[2022-10-14T13:28:12.520+0000] {taskinstance.py:1592} INFO - Exporting the following env vars:
AIRFLOW_CTX_DAG_OWNER=***
AIRFLOW_CTX_DAG_ID=DAG_cines
AIRFLOW_CTX_TASK_ID=get_data
AIRFLOW_CTX_EXECUTION_DATE=2022-10-14T13:28:06.360505+00:00
AIRFLOW_CTX_TRY_NUMBER=1
AIRFLOW_CTX_DAG_RUN_ID=manual__2022-10-14T13:28:06.360505+00:00
[2022-10-14T13:28:14.862+0000] {taskinstance.py:1851} ERROR - Task failed with exception
Traceback (most recent call last):
  File "/home/airflow/.local/lib/python3.7/site-packages/airflow/operators/python.py", line 175, in execute
    return_value = self.execute_callable()
  File "/home/airflow/.local/lib/python3.7/site-packages/airflow/operators/python.py", line 193, in execute_callable
    return self.python_callable(*self.op_args, **self.op_kwargs)
  File "/opt/airflow/dags/DD_template.py", line 76, in get_data
    raise "manualy stopped"
TypeError: exceptions must derive from BaseException
[2022-10-14T13:28:15.099+0000] {taskinstance.py:1406} INFO - Marking task as FAILED. dag_id=DAG_cines, task_id=get_data, execution_date=20221014T132806, start_date=20221014T132809, end_date=20221014T132815
[2022-10-14T13:28:15.180+0000] {standard_task_runner.py:107} ERROR - Failed to execute job 92 for task get_data (exceptions must derive from BaseException; 119)
[2022-10-14T13:28:15.485+0000] {local_task_job.py:164} INFO - Task exited with return code 1
[2022-10-14T13:28:15.657+0000] {local_task_job.py:273} INFO - 0 downstream tasks scheduled from follow-on schedule check
