[2022-10-14T22:02:01.948+0000] {taskinstance.py:1165} INFO - Dependencies all met for <TaskInstance: DAG_cines.load_data manual__2022-10-14T22:01:56.966014+00:00 [queued]>
[2022-10-14T22:02:01.957+0000] {taskinstance.py:1165} INFO - Dependencies all met for <TaskInstance: DAG_cines.load_data manual__2022-10-14T22:01:56.966014+00:00 [queued]>
[2022-10-14T22:02:01.958+0000] {taskinstance.py:1362} INFO - 
--------------------------------------------------------------------------------
[2022-10-14T22:02:01.960+0000] {taskinstance.py:1363} INFO - Starting attempt 1 of 1
[2022-10-14T22:02:01.961+0000] {taskinstance.py:1364} INFO - 
--------------------------------------------------------------------------------
[2022-10-14T22:02:01.972+0000] {taskinstance.py:1383} INFO - Executing <Task(PythonOperator): load_data> on 2022-10-14 22:01:56.966014+00:00
[2022-10-14T22:02:01.978+0000] {standard_task_runner.py:54} INFO - Started process 1053 to run task
[2022-10-14T22:02:01.981+0000] {standard_task_runner.py:82} INFO - Running: ['***', 'tasks', 'run', 'DAG_cines', 'load_data', 'manual__2022-10-14T22:01:56.966014+00:00', '--job-id', '126', '--raw', '--subdir', 'DAGS_FOLDER/DD_template.py', '--cfg-path', '/tmp/tmpzuxouyeu']
[2022-10-14T22:02:01.984+0000] {standard_task_runner.py:83} INFO - Job 126: Subtask load_data
[2022-10-14T22:02:01.986+0000] {dagbag.py:525} INFO - Filling up the DagBag from /opt/***/dags/DD_template.py
[2022-10-14T22:02:02.093+0000] {task_command.py:384} INFO - Running <TaskInstance: DAG_cines.load_data manual__2022-10-14T22:01:56.966014+00:00 [running]> on host e0ff8f96cc52
[2022-10-14T22:02:02.158+0000] {taskinstance.py:1592} INFO - Exporting the following env vars:
AIRFLOW_CTX_DAG_OWNER=***
AIRFLOW_CTX_DAG_ID=DAG_cines
AIRFLOW_CTX_TASK_ID=load_data
AIRFLOW_CTX_EXECUTION_DATE=2022-10-14T22:01:56.966014+00:00
AIRFLOW_CTX_TRY_NUMBER=1
AIRFLOW_CTX_DAG_RUN_ID=manual__2022-10-14T22:01:56.966014+00:00
[2022-10-14T22:02:02.862+0000] {taskinstance.py:1851} ERROR - Task failed with exception
Traceback (most recent call last):
  File "/home/airflow/.local/lib/python3.7/site-packages/airflow/operators/python.py", line 175, in execute
    return_value = self.execute_callable()
  File "/home/airflow/.local/lib/python3.7/site-packages/airflow/operators/python.py", line 193, in execute_callable
    return self.python_callable(*self.op_args, **self.op_kwargs)
  File "/opt/airflow/dags/DD_template.py", line 330, in load_data
    r'datasets/bibliotecas_data.csv'
  File "/home/airflow/.local/lib/python3.7/site-packages/boto3/s3/inject.py", line 148, in upload_file
    callback=Callback,
  File "/home/airflow/.local/lib/python3.7/site-packages/boto3/s3/transfer.py", line 288, in upload_file
    future.result()
  File "/home/airflow/.local/lib/python3.7/site-packages/s3transfer/futures.py", line 103, in result
    return self._coordinator.result()
  File "/home/airflow/.local/lib/python3.7/site-packages/s3transfer/futures.py", line 266, in result
    raise self._exception
  File "/home/airflow/.local/lib/python3.7/site-packages/s3transfer/tasks.py", line 269, in _main
    self._submit(transfer_future=transfer_future, **kwargs)
  File "/home/airflow/.local/lib/python3.7/site-packages/s3transfer/upload.py", line 585, in _submit
    upload_input_manager.provide_transfer_size(transfer_future)
  File "/home/airflow/.local/lib/python3.7/site-packages/s3transfer/upload.py", line 244, in provide_transfer_size
    self._osutil.get_file_size(transfer_future.meta.call_args.fileobj)
  File "/home/airflow/.local/lib/python3.7/site-packages/s3transfer/utils.py", line 247, in get_file_size
    return os.path.getsize(filename)
  File "/usr/local/lib/python3.7/genericpath.py", line 50, in getsize
    return os.stat(filename).st_size
FileNotFoundError: [Errno 2] No such file or directory: '../datasets/bibliotecas/previous_bibliotecas_data.csv'
[2022-10-14T22:02:02.880+0000] {taskinstance.py:1406} INFO - Marking task as FAILED. dag_id=DAG_cines, task_id=load_data, execution_date=20221014T220156, start_date=20221014T220201, end_date=20221014T220202
[2022-10-14T22:02:02.891+0000] {standard_task_runner.py:107} ERROR - Failed to execute job 126 for task load_data ([Errno 2] No such file or directory: '../datasets/bibliotecas/previous_bibliotecas_data.csv'; 1053)
[2022-10-14T22:02:02.935+0000] {local_task_job.py:164} INFO - Task exited with return code 1
[2022-10-14T22:02:02.969+0000] {local_task_job.py:273} INFO - 0 downstream tasks scheduled from follow-on schedule check
