[2022-10-14T22:20:19.878+0000] {taskinstance.py:1165} INFO - Dependencies all met for <TaskInstance: DAG_cines.load_data manual__2022-10-14T22:20:14.733023+00:00 [queued]>
[2022-10-14T22:20:19.884+0000] {taskinstance.py:1165} INFO - Dependencies all met for <TaskInstance: DAG_cines.load_data manual__2022-10-14T22:20:14.733023+00:00 [queued]>
[2022-10-14T22:20:19.885+0000] {taskinstance.py:1362} INFO - 
--------------------------------------------------------------------------------
[2022-10-14T22:20:19.886+0000] {taskinstance.py:1363} INFO - Starting attempt 1 of 1
[2022-10-14T22:20:19.887+0000] {taskinstance.py:1364} INFO - 
--------------------------------------------------------------------------------
[2022-10-14T22:20:19.895+0000] {taskinstance.py:1383} INFO - Executing <Task(PythonOperator): load_data> on 2022-10-14 22:20:14.733023+00:00
[2022-10-14T22:20:19.900+0000] {standard_task_runner.py:54} INFO - Started process 2028 to run task
[2022-10-14T22:20:19.904+0000] {standard_task_runner.py:82} INFO - Running: ['***', 'tasks', 'run', 'DAG_cines', 'load_data', 'manual__2022-10-14T22:20:14.733023+00:00', '--job-id', '134', '--raw', '--subdir', 'DAGS_FOLDER/DD_template.py', '--cfg-path', '/tmp/tmpz_pegezh']
[2022-10-14T22:20:19.906+0000] {standard_task_runner.py:83} INFO - Job 134: Subtask load_data
[2022-10-14T22:20:19.908+0000] {dagbag.py:525} INFO - Filling up the DagBag from /opt/***/dags/DD_template.py
[2022-10-14T22:20:20.020+0000] {task_command.py:384} INFO - Running <TaskInstance: DAG_cines.load_data manual__2022-10-14T22:20:14.733023+00:00 [running]> on host e0ff8f96cc52
[2022-10-14T22:20:20.060+0000] {taskinstance.py:1592} INFO - Exporting the following env vars:
AIRFLOW_CTX_DAG_OWNER=***
AIRFLOW_CTX_DAG_ID=DAG_cines
AIRFLOW_CTX_TASK_ID=load_data
AIRFLOW_CTX_EXECUTION_DATE=2022-10-14T22:20:14.733023+00:00
AIRFLOW_CTX_TRY_NUMBER=1
AIRFLOW_CTX_DAG_RUN_ID=manual__2022-10-14T22:20:14.733023+00:00
[2022-10-14T22:20:26.357+0000] {taskinstance.py:1851} ERROR - Task failed with exception
Traceback (most recent call last):
  File "/home/airflow/.local/lib/python3.7/site-packages/boto3/s3/transfer.py", line 288, in upload_file
    future.result()
  File "/home/airflow/.local/lib/python3.7/site-packages/s3transfer/futures.py", line 103, in result
    return self._coordinator.result()
  File "/home/airflow/.local/lib/python3.7/site-packages/s3transfer/futures.py", line 266, in result
    raise self._exception
  File "/home/airflow/.local/lib/python3.7/site-packages/s3transfer/tasks.py", line 139, in __call__
    return self._execute_main(kwargs)
  File "/home/airflow/.local/lib/python3.7/site-packages/s3transfer/tasks.py", line 162, in _execute_main
    return_value = self._main(**kwargs)
  File "/home/airflow/.local/lib/python3.7/site-packages/s3transfer/upload.py", line 758, in _main
    client.put_object(Bucket=bucket, Key=key, Body=body, **extra_args)
  File "/home/airflow/.local/lib/python3.7/site-packages/botocore/client.py", line 514, in _api_call
    return self._make_api_call(operation_name, kwargs)
  File "/home/airflow/.local/lib/python3.7/site-packages/botocore/client.py", line 938, in _make_api_call
    raise error_class(parsed_response, operation_name)
botocore.exceptions.ClientError: An error occurred (SignatureDoesNotMatch) when calling the PutObject operation: The request signature we calculated does not match the signature you provided. Check your key and signing method.

During handling of the above exception, another exception occurred:

Traceback (most recent call last):
  File "/home/airflow/.local/lib/python3.7/site-packages/airflow/operators/python.py", line 175, in execute
    return_value = self.execute_callable()
  File "/home/airflow/.local/lib/python3.7/site-packages/airflow/operators/python.py", line 193, in execute_callable
    return self.python_callable(*self.op_args, **self.op_kwargs)
  File "/opt/airflow/dags/DD_template.py", line 330, in load_data
    r'datasets/bibliotecas/bibliotecas_data.csv'
  File "/home/airflow/.local/lib/python3.7/site-packages/boto3/s3/inject.py", line 148, in upload_file
    callback=Callback,
  File "/home/airflow/.local/lib/python3.7/site-packages/boto3/s3/transfer.py", line 296, in upload_file
    filename, '/'.join([bucket, key]), e
boto3.exceptions.S3UploadFailedError: Failed to upload datasets/bibliotecas/previous_bibliotecas_data.csv to ***dockerbucket/datasets/bibliotecas/bibliotecas_data.csv: An error occurred (SignatureDoesNotMatch) when calling the PutObject operation: The request signature we calculated does not match the signature you provided. Check your key and signing method.
[2022-10-14T22:20:26.407+0000] {taskinstance.py:1406} INFO - Marking task as FAILED. dag_id=DAG_cines, task_id=load_data, execution_date=20221014T222014, start_date=20221014T222019, end_date=20221014T222026
[2022-10-14T22:20:26.424+0000] {standard_task_runner.py:107} ERROR - Failed to execute job 134 for task load_data (Failed to upload datasets/bibliotecas/previous_bibliotecas_data.csv to ***dockerbucket/datasets/bibliotecas/bibliotecas_data.csv: An error occurred (SignatureDoesNotMatch) when calling the PutObject operation: The request signature we calculated does not match the signature you provided. Check your key and signing method.; 2028)
[2022-10-14T22:20:26.520+0000] {local_task_job.py:164} INFO - Task exited with return code 1
[2022-10-14T22:20:26.536+0000] {local_task_job.py:273} INFO - 0 downstream tasks scheduled from follow-on schedule check
