[2022-10-17T14:25:24.081+0000] {taskinstance.py:1165} INFO - Dependencies all met for <TaskInstance: DAG_cine.transform_data manual__2022-10-17T14:25:20.316850+00:00 [queued]>
[2022-10-17T14:25:24.094+0000] {taskinstance.py:1165} INFO - Dependencies all met for <TaskInstance: DAG_cine.transform_data manual__2022-10-17T14:25:20.316850+00:00 [queued]>
[2022-10-17T14:25:24.095+0000] {taskinstance.py:1362} INFO - 
--------------------------------------------------------------------------------
[2022-10-17T14:25:24.096+0000] {taskinstance.py:1363} INFO - Starting attempt 1 of 1
[2022-10-17T14:25:24.097+0000] {taskinstance.py:1364} INFO - 
--------------------------------------------------------------------------------
[2022-10-17T14:25:24.106+0000] {taskinstance.py:1383} INFO - Executing <Task(PythonOperator): transform_data> on 2022-10-17 14:25:20.316850+00:00
[2022-10-17T14:25:24.111+0000] {standard_task_runner.py:54} INFO - Started process 105 to run task
[2022-10-17T14:25:24.114+0000] {standard_task_runner.py:82} INFO - Running: ['***', 'tasks', 'run', 'DAG_cine', 'transform_data', 'manual__2022-10-17T14:25:20.316850+00:00', '--job-id', '168', '--raw', '--subdir', 'DAGS_FOLDER/DAG_cine.py', '--cfg-path', '/tmp/tmp_lbasbs3']
[2022-10-17T14:25:24.116+0000] {standard_task_runner.py:83} INFO - Job 168: Subtask transform_data
[2022-10-17T14:25:24.118+0000] {dagbag.py:525} INFO - Filling up the DagBag from /opt/***/dags/DAG_cine.py
[2022-10-17T14:25:24.452+0000] {task_command.py:384} INFO - Running <TaskInstance: DAG_cine.transform_data manual__2022-10-17T14:25:20.316850+00:00 [running]> on host 067073ba6286
[2022-10-17T14:25:24.498+0000] {taskinstance.py:1592} INFO - Exporting the following env vars:
AIRFLOW_CTX_DAG_OWNER=***
AIRFLOW_CTX_DAG_ID=DAG_cine
AIRFLOW_CTX_TASK_ID=transform_data
AIRFLOW_CTX_EXECUTION_DATE=2022-10-17T14:25:20.316850+00:00
AIRFLOW_CTX_TRY_NUMBER=1
AIRFLOW_CTX_DAG_RUN_ID=manual__2022-10-17T14:25:20.316850+00:00
[2022-10-17T14:25:24.512+0000] {taskinstance.py:1851} ERROR - Task failed with exception
Traceback (most recent call last):
  File "/home/airflow/.local/lib/python3.7/site-packages/pandas/core/indexes/base.py", line 3361, in get_loc
    return self._engine.get_loc(casted_key)
  File "pandas/_libs/index.pyx", line 76, in pandas._libs.index.IndexEngine.get_loc
  File "pandas/_libs/index.pyx", line 108, in pandas._libs.index.IndexEngine.get_loc
  File "pandas/_libs/hashtable_class_helper.pxi", line 5198, in pandas._libs.hashtable.PyObjectHashTable.get_item
  File "pandas/_libs/hashtable_class_helper.pxi", line 5206, in pandas._libs.hashtable.PyObjectHashTable.get_item
KeyError: 'actualizacion'

The above exception was the direct cause of the following exception:

Traceback (most recent call last):
  File "/home/airflow/.local/lib/python3.7/site-packages/airflow/operators/python.py", line 175, in execute
    return_value = self.execute_callable()
  File "/home/airflow/.local/lib/python3.7/site-packages/airflow/operators/python.py", line 193, in execute_callable
    return self.python_callable(*self.op_args, **self.op_kwargs)
  File "/opt/airflow/dags/DAG_cine.py", line 241, in transform_data
    last = clean_columns(last)
  File "/opt/airflow/dags/DAG_cine.py", line 199, in clean_columns
    dataframe['actualizacion'].values
  File "/home/airflow/.local/lib/python3.7/site-packages/pandas/core/frame.py", line 3458, in __getitem__
    indexer = self.columns.get_loc(key)
  File "/home/airflow/.local/lib/python3.7/site-packages/pandas/core/indexes/base.py", line 3363, in get_loc
    raise KeyError(key) from err
KeyError: 'actualizacion'
[2022-10-17T14:25:24.522+0000] {taskinstance.py:1406} INFO - Marking task as FAILED. dag_id=DAG_cine, task_id=transform_data, execution_date=20221017T142520, start_date=20221017T142524, end_date=20221017T142524
[2022-10-17T14:25:24.531+0000] {standard_task_runner.py:107} ERROR - Failed to execute job 168 for task transform_data ('actualizacion'; 105)
[2022-10-17T14:25:24.575+0000] {local_task_job.py:164} INFO - Task exited with return code 1
[2022-10-17T14:25:24.598+0000] {local_task_job.py:273} INFO - 0 downstream tasks scheduled from follow-on schedule check
