[2022-10-14T21:50:33.560+0000] {taskinstance.py:1165} INFO - Dependencies all met for <TaskInstance: DAG_cines.load_data manual__2022-10-14T21:50:28.355442+00:00 [queued]>
[2022-10-14T21:50:33.570+0000] {taskinstance.py:1165} INFO - Dependencies all met for <TaskInstance: DAG_cines.load_data manual__2022-10-14T21:50:28.355442+00:00 [queued]>
[2022-10-14T21:50:33.571+0000] {taskinstance.py:1362} INFO - 
--------------------------------------------------------------------------------
[2022-10-14T21:50:33.573+0000] {taskinstance.py:1363} INFO - Starting attempt 1 of 1
[2022-10-14T21:50:33.574+0000] {taskinstance.py:1364} INFO - 
--------------------------------------------------------------------------------
[2022-10-14T21:50:33.585+0000] {taskinstance.py:1383} INFO - Executing <Task(PythonOperator): load_data> on 2022-10-14 21:50:28.355442+00:00
[2022-10-14T21:50:33.594+0000] {standard_task_runner.py:54} INFO - Started process 475 to run task
[2022-10-14T21:50:33.598+0000] {standard_task_runner.py:82} INFO - Running: ['***', 'tasks', 'run', 'DAG_cines', 'load_data', 'manual__2022-10-14T21:50:28.355442+00:00', '--job-id', '123', '--raw', '--subdir', 'DAGS_FOLDER/DD_template.py', '--cfg-path', '/tmp/tmpya3zmwvv']
[2022-10-14T21:50:33.604+0000] {standard_task_runner.py:83} INFO - Job 123: Subtask load_data
[2022-10-14T21:50:33.609+0000] {dagbag.py:525} INFO - Filling up the DagBag from /opt/***/dags/DD_template.py
[2022-10-14T21:50:33.741+0000] {task_command.py:384} INFO - Running <TaskInstance: DAG_cines.load_data manual__2022-10-14T21:50:28.355442+00:00 [running]> on host e0ff8f96cc52
[2022-10-14T21:50:33.816+0000] {taskinstance.py:1592} INFO - Exporting the following env vars:
AIRFLOW_CTX_DAG_OWNER=***
AIRFLOW_CTX_DAG_ID=DAG_cines
AIRFLOW_CTX_TASK_ID=load_data
AIRFLOW_CTX_EXECUTION_DATE=2022-10-14T21:50:28.355442+00:00
AIRFLOW_CTX_TRY_NUMBER=1
AIRFLOW_CTX_DAG_RUN_ID=manual__2022-10-14T21:50:28.355442+00:00
[2022-10-14T21:50:33.837+0000] {taskinstance.py:1851} ERROR - Task failed with exception
Traceback (most recent call last):
  File "/home/airflow/.local/lib/python3.7/site-packages/airflow/operators/python.py", line 175, in execute
    return_value = self.execute_callable()
  File "/home/airflow/.local/lib/python3.7/site-packages/airflow/operators/python.py", line 193, in execute_callable
    return self.python_callable(*self.op_args, **self.op_kwargs)
  File "/opt/airflow/dags/DD_template.py", line 333, in load_data
    replace=True
  File "/home/airflow/.local/lib/python3.7/site-packages/airflow/providers/amazon/aws/hooks/s3.py", line 60, in wrapper
    connection = self.get_connection(self.aws_conn_id)
  File "/home/airflow/.local/lib/python3.7/site-packages/airflow/hooks/base.py", line 70, in get_connection
    conn = Connection.get_connection_from_secrets(conn_id)
  File "/home/airflow/.local/lib/python3.7/site-packages/airflow/models/connection.py", line 432, in get_connection_from_secrets
    raise AirflowNotFoundException(f"The conn_id `{conn_id}` isn't defined")
airflow.exceptions.AirflowNotFoundException: The conn_id `files` isn't defined
[2022-10-14T21:50:33.847+0000] {taskinstance.py:1406} INFO - Marking task as FAILED. dag_id=DAG_cines, task_id=load_data, execution_date=20221014T215028, start_date=20221014T215033, end_date=20221014T215033
[2022-10-14T21:50:33.858+0000] {standard_task_runner.py:107} ERROR - Failed to execute job 123 for task load_data (The conn_id `files` isn't defined; 475)
[2022-10-14T21:50:33.895+0000] {local_task_job.py:164} INFO - Task exited with return code 1
[2022-10-14T21:50:33.918+0000] {local_task_job.py:273} INFO - 0 downstream tasks scheduled from follow-on schedule check
